Workbook

Sheet Definitions
B3: FFRM
B4: Fossil Fuel Retirement Model
B7: FFRM Input File - Guide
B9: Document structure | E9: Version 1.0
B11: Other | E11: The Fossil Fuel Retirement Model (FFRM), is a ….
B12: Plant Data
B13: FC_PPA
B14: Price_Gen
B15: Price_Distribution
B17: Parameter Constraints | D17: - | E17: CCG in Collaboration With:
B18: Name | C18: Description | D18: -
B19: Capacity (MW) | D19: -
B20: Capital Cost | C20: The parameter capital cost refers to the initial investment required for the construction or acquisition of long-term energy infrastructure, such as power plants or renewable energy systems, typically expressed in $/kW. | D20: -
B21: CostEsc_10-30years | C21: CAGR at which plant varible costs are escalated, for plants between 10 and 30 years old | D21: -
B22: CostEsc_30plus | C22: CAGR at which plant varible costs are escalated, for plants older than 30 years | D22: - | G22: -
B23: CostEsc_Lessthan10 | C23: CAGR at which plant varible costs are escalated, for plants less than 10 years old | D23: - | E23: Scenarios | G23: - | H23: Technologies
B24: Discount Rate | C24: The parameter discount rate refers to the rate used to discount future cash flows to their present value, based on the future weighted average cost of capital (WACC). | D24: - | E24: Name | F24: Description | G24: - | H24: Name | I24: Description
B25: Electricity Production | C25: The parameter electricity production refers to the total amount of electricity generated at a national scale, expressed in petajoules (PJ). | D25: - | E25: BAU | F25: Scenario Name 1 (Baseline) | G25: - | H25: PWRCOA001 | I25: Coal power plant
B26: Fixed Cost | C26: The parameter fixed cost refers to the ongoing expenses that remain constant over time, regardless of the level of energy production, such as maintenance or operational costs, typically expressed in millions of USD. | D26: - | E26: AD | F26: Scenario Name 2 (More Ambitious) | G26: - | H26: PWROHC001 | I26: Light fuel oil power plant
B27: Generation (TWh) | D27: - | G27: - | H27: PWROHC002 | I27: Oil fired gas turbine - SCGT
B28: Interest Rate | D28: - | G28: - | H28: PWRNGS001 | I28: Natural gas power plant - CCGT
B29: Loan Term | D29: - | G29: - | H29: PWRNGS002 | I29: Nautral gas power plant - SCGT
B30: Marginal Revenue ($/MWh) | D30: - | G30: - | H30: PWROHC003 | I30: Light fuel oil standalone generator (1kW)
B31: Market Price ($/MWh) | D31: - | G31: -
B32: MaxLife | C32: Max life beyond which plant must be retired | D32: - | G32: -
B33: MaxPLF | C33: Max PLF | D33: - | E33: Consumer Segments | G33: - | H33: Start Year | I33: 44197
B34: MinPLF | C34: Minimum PLF below which plant is retired | D34: - | E34: Name | F34: Description | G34: - | H34: End Year | I34: 62094
B35: Name of Project | C35: The name of the project receiving financing. | D35: - | E35: Residential | F35: Households and individual consumers that use electricity for daily living activities, such as lighting, appliances, and heating. | G35: -
B36: Plant Name | D36: - | E36: Commercial | F36: Businesses and small enterprises that require electricity to power operations, including office equipment, lighting, and HVAC systems. | G36: -
B37: Plant Type | D37: - | E37: Industrial | F37: Large-scale manufacturers and factories that consume high levels of energy to operate machinery, production lines, and other industrial processes. | G37: -
B38: PPA Price ($/MWh) | D38: - | G38: -
B39: Price Regime | D39: - | G39: -
B40: Share of Generation | D40: - | G40: -
B41: Start Year | D41: -
B42: Straight-line depreciation | C42: Straight-line depreciation | D42: -
B43: Tariff | D43: -
B44: MinCapacity | C44: This parameter relates to
B45: Variable Cost | C45: The parameter variable cost refers to the expenses that change in direct proportion to the level of energy production or consumption, such as fuel or operational costs, typically expressed in millions of USD. | D45: -

Sheet Other
A1: FFRM
A2: Other
A3: Variable | B3: Technology | C3: Value
A4: Interest Rate | B4: =IF(Definitions!H25="","",Definitions!H25) -> PWRCOA001 | C4: 0.05
A5: Interest Rate | B5: =IF(Definitions!H26="","",Definitions!H26) -> PWROHC001 | C5: 0
A6: Interest Rate | B6: =IF(Definitions!H27="","",Definitions!H27) -> PWROHC002 | C6: 0
A7: Interest Rate | B7: =IF(Definitions!H28="","",Definitions!H28) -> PWRNGS001 | C7: 0
A8: Interest Rate | B8: =IF(Definitions!H29="","",Definitions!H29) -> PWRNGS002 | C8: 0
A9: Interest Rate | B9: =IF(Definitions!H30="","",Definitions!H30) -> PWROHC003 | C9: 0
A10: Interest Rate | B10: =IF(Definitions!H31="","",Definitions!H31) | C10: 0
A11: Loan Term | B11: =IF(Definitions!H25="","",Definitions!H25) -> PWRCOA001 | C11: 15
A12: Loan Term | B12: =IF(Definitions!H26="","",Definitions!H26) -> PWROHC001 | C12: 0
A13: Loan Term | B13: =IF(Definitions!H27="","",Definitions!H27) -> PWROHC002 | C13: 0
A14: Loan Term | B14: =IF(Definitions!H28="","",Definitions!H28) -> PWRNGS001 | C14: 0
A15: Loan Term | B15: =IF(Definitions!H29="","",Definitions!H29) -> PWRNGS002 | C15: 0
A16: Loan Term | B16: =IF(Definitions!H30="","",Definitions!H30) -> PWROHC003 | C16: 0
A17: Loan Term | B17: =IF(Definitions!H31="","",Definitions!H31) | C17: 0
A18: DiscountRate | B18: =IF(Definitions!H25="","",Definitions!H25) -> PWRCOA001 | C18: 0.06
A19: Straight-line depreciation | B19: =IF(Definitions!H25="","",Definitions!H25) -> PWRCOA001 | C19: 0.025
A20: CoalCapex $/kW | B20: =IF(Definitions!H25="","",Definitions!H25) -> PWRCOA001 | C20: 100
A21: CostEsc_Lessthan10 | B21: =IF(Definitions!H25="","",Definitions!H25) -> PWRCOA001 | C21: 0.005
A22: CostEsc_10-30years | B22: =IF(Definitions!H25="","",Definitions!H25) -> PWRCOA001 | C22: 0.01
A23: CostEsc_30plus | B23: =IF(Definitions!H25="","",Definitions!H25) -> PWRCOA001 | C23: 0.015
A24: MinPLF | B24: =IF(Definitions!H25="","",Definitions!H25) -> PWRCOA001 | C24: 0.25
A25: MaxPLF | B25: =IF(Definitions!H25="","",Definitions!H25) -> PWRCOA001 | C25: 0.85
A26: MaxLife | B26: =IF(Definitions!H25="","",Definitions!H25) -> PWRCOA001 | C26: 40
A27: DiscountRate | B27: =IF(Definitions!H26="","",Definitions!H26) -> PWROHC001 | C27: 0
A28: Straight-line depreciation | B28: =IF(Definitions!H26="","",Definitions!H26) -> PWROHC001 | C28: 0
A29: CoalCapex $/kW | B29: =IF(Definitions!H26="","",Definitions!H26) -> PWROHC001 | C29: 0
A30: CostEsc_Lessthan10 | B30: =IF(Definitions!H26="","",Definitions!H26) -> PWROHC001 | C30: 0
A31: CostEsc_10-30years | B31: =IF(Definitions!H26="","",Definitions!H26) -> PWROHC001 | C31: 0
A32: CostEsc_30plus | B32: =IF(Definitions!H26="","",Definitions!H26) -> PWROHC001 | C32: 0
A33: MinPLF | B33: =IF(Definitions!H26="","",Definitions!H26) -> PWROHC001 | C33: 0
A34: MaxPLF | B34: =IF(Definitions!H26="","",Definitions!H26) -> PWROHC001 | C34: 0
A35: MaxLife | B35: =IF(Definitions!H26="","",Definitions!H26) -> PWROHC001 | C35: 0
A36: DiscountRate | B36: =IF(Definitions!H27="","",Definitions!H27) -> PWROHC002 | C36: 0
A37: Straight-line depreciation | B37: =IF(Definitions!H27="","",Definitions!H27) -> PWROHC002 | C37: 0
A38: CoalCapex $/kW | B38: =IF(Definitions!H27="","",Definitions!H27) -> PWROHC002 | C38: 0
A39: CostEsc_Lessthan10 | B39: =IF(Definitions!H27="","",Definitions!H27) -> PWROHC002 | C39: 0
A40: CostEsc_10-30years | B40: =IF(Definitions!H27="","",Definitions!H27) -> PWROHC002 | C40: 0
...

Sheet Plant Data
A1: FFRM
A2: Plant Data
A3: Plant Name | B3: Variable Cost ($/MWh) | C3: Fixed Cost ($/MWh) | D3: PPA Price ($/MWh) | E3: Market Price ($/MWh) | F3: Capacity (MW) | G3: Start Year | H3: Plant Type | I3: Price Regime | J3: ContractPriceMW
A4: MORUPULE A POWER STATION UNIT 1 | B4: 5.9 | C4: 58.33 | D4: 100 | E4: 2 | F4: 33 | G4: 1986 | H4: PWRCOA001 | I4: PPA | J4: 0
A5: MORUPULE A POWER STATION UNIT 2 | B5: 5.9 | C5: 58.33 | D5: 100 | E5: 2 | F5: 33 | G5: 1986 | H5: PWRCOA001 | I5: PPA | J5: 0
A6: MORUPULE A POWER STATION UNIT 3 | B6: 5.9 | C6: 58.33 | D6: 100 | E6: 2 | F6: 33 | G6: 1987 | H6: PWRCOA001 | I6: PPA | J6: 0
A7: MORUPULE A POWER STATION UNIT 4 | B7: 5.9 | C7: 58.33 | D7: 100 | E7: 2 | F7: 33 | G7: 1989 | H7: PWRCOA001 | I7: PPA | J7: 0
A8: MORUPULE B POWER STATION UNIT 1 | B8: 5.9 | C8: 58.33 | D8: 100 | E8: 2 | F8: 150 | G8: 2013 | H8: PWRCOA001 | I8: PPA | J8: 0
A9: MORUPULE B POWER STATION UNIT 2 | B9: 5.9 | C9: 58.33 | D9: 100 | E9: 2 | F9: 150 | G9: 2013 | H9: PWRCOA001 | I9: PPA | J9: 0
A10: MORUPULE B POWER STATION UNIT 3 | B10: 5.9 | C10: 58.33 | D10: 100 | E10: 2 | F10: 150 | G10: 2014 | H10: PWRCOA001 | I10: PPA | J10: 0
A11: MORUPULE B POWER STATION UNIT 4 | B11: 5.9 | C11: 58.33 | D11: 100 | E11: 2 | F11: 150 | G11: 2014 | H11: PWRCOA001 | I11: PPA | J11: 0
A12: MMAMABULA ENERGY PROJECT UNIT 1 | B12: 5.9 | C12: 58.33 | D12: 100 | E12: 2 | F12: 150 | G12: 2026 | H12: PWRCOA001 | I12: PPA | J12: 0
A13: MMAMABULA ENERGY PROJECT UNIT 2 | B13: 5.9 | C13: 58.33 | D13: 100 | E13: 2 | F13: 150 | G13: 2027 | H13: PWRCOA001 | I13: PPA | J13: 0
A14: MMAMABULA ENERGY PROJECT UNIT 3 | B14: 5.9 | C14: 58.33 | D14: 100 | E14: 2 | F14: 150 | G14: 2027 | H14: PWRCOA001 | I14: PPA | J14: 0
A15: MMAMABULA ENERGY PROJECT UNIT 4 | B15: 5.9 | C15: 58.33 | D15: 100 | E15: 2 | F15: 150 | G15: 2027 | H15: PWRCOA001 | I15: PPA | J15: 0

Sheet FC_PPA
A1: FFRM
A2: PPA
A3: Plant Name | B3: =Definitions!I33 -> 44197 | C3: =IFERROR(IF(EDATE(B3,12)<(Definitions!$I$34+1),EDATE(B3,12),""),"") -> 44562 | D3: =IFERROR(IF(EDATE(C3,12)<(Definitions!$I$34+1),EDATE(C3,12),""),"") -> 44927 | E3: =IFERROR(IF(EDATE(D3,12)<(Definitions!$I$34+1),EDATE(D3,12),""),"") -> 45292 | F3: =IFERROR(IF(EDATE(E3,12)<(Definitions!$I$34+1),EDATE(E3,12),""),"") -> 45658 | G3: =IFERROR(IF(EDATE(F3,12)<(Definitions!$I$34+1),EDATE(F3,12),""),"") -> 46023 | H3: =IFERROR(IF(EDATE(G3,12)<(Definitions!$I$34+1),EDATE(G3,12),""),"") -> 46388 | I3: =IFERROR(IF(EDATE(H3,12)<(Definitions!$I$34+1),EDATE(H3,12),""),"") -> 46753 | J3: =IFERROR(IF(EDATE(I3,12)<(Definitions!$I$34+1),EDATE(I3,12),""),"") -> 47119 | ... AY3: =IFERROR(IF(EDATE(AX3,12)<(Definitions!$I$34+1),EDATE(AX3,12),""),"") -> 62094
A4: =IF('Plant Data'!A4="","",'Plant Data'!A4) -> MORUPULE A POWER STATION UNIT 1 | B4: =('Plant Data'!$C4*0.85*8760) -> 434325.18 | C4: =('Plant Data'!$C4*0.85*8760) -> 434325.18 | D4: =('Plant Data'!$C4*0.85*8760) -> 434325.18 | E4: =('Plant Data'!$C4*0.85*8760) -> 434325.18 | F4: =('Plant Data'!$C4*0.85*8760) -> 434325.18 | G4: =('Plant Data'!$C4*0.85*8760) -> 434325.18 | H4: =('Plant Data'!$C4*0.85*8760) -> 434325.18 | I4: 0 | J4: 0 | K4: 0 | L4: 0 | M4: 0 | N4: 0 | O4: 0 | P4: 0 | Q4: 0 | R4: 0 | S4: 0 | T4: 0 | U4: 0 | V4: 0 | W4: 0 | X4: 0 | Y4: 0 | Z4: 0 | AA4: 0 | AB4: 0 | AC4: 0 | AD4: 0 | AE4: 0 | AF4: 0 | AG4: 0 | AH4: 0 | AI4: 0 | AJ4: 0 | AK4: 0 | AL4: 0 | AM4: 0 | AN4: 0 | AO4: 0 | AP4: 0 | AQ4: 0 | AR4: 0 | AS4: 0 | AT4: 0 | AU4: 0 | AV4: 0 | AW4: 0 | AX4: 0 | AY4: 0
A5: =IF('Plant Data'!A5="","",'Plant Data'!A5) -> MORUPULE A POWER STATION UNIT 2 | B5: =('Plant Data'!C5*0.85*8760) -> 434325.18 | C5: =('Plant Data'!$C5*0.85*8760) -> 434325.18 | D5: =('Plant Data'!$C5*0.85*8760) -> 434325.18 | E5: =('Plant Data'!$C5*0.85*8760) -> 434325.18 | F5: =('Plant Data'!$C5*0.85*8760) -> 434325.18 | G5: =('Plant Data'!$C5*0.85*8760) -> 434325.18 | H5: =('Plant Data'!$C5*0.85*8760) -> 434325.18 | I5: 0 | J5: 0 | K5: 0 | L5: 0 | M5: 0 | N5: 0 | O5: 0 | P5: 0 | Q5: 0 | R5: 0 | S5: 0 | T5: 0 | U5: 0 | V5: 0 | W5: 0 | X5: 0 | Y5: 0 | Z5: 0 | AA5: 0 | AB5: 0 | AC5: 0 | AD5: 0 | AE5: 0 | AF5: 0 | AG5: 0 | AH5: 0 | AI5: 0 | AJ5: 0 | AK5: 0 | AL5: 0 | AM5: 0 | AN5: 0 | AO5: 0 | AP5: 0 | AQ5: 0 | AR5: 0 | AS5: 0 | AT5: 0 | AU5: 0 | AV5: 0 | AW5: 0 | AX5: 0 | AY5: 0
A6: =IF('Plant Data'!A6="","",'Plant Data'!A6) -> MORUPULE A POWER STATION UNIT 3 | B6: =('Plant Data'!C6*0.85*8760) -> 434325.18 | C6: =('Plant Data'!$C6*0.85*8760) -> 434325.18 | D6: =('Plant Data'!$C6*0.85*8760) -> 434325.18 | E6: =('Plant Data'!$C6*0.85*8760) -> 434325.18 | F6: =('Plant Data'!$C6*0.85*8760) -> 434325.18 | G6: =('Plant Data'!$C6*0.85*8760) -> 434325.18 | H6: =('Plant Data'!$C6*0.85*8760) -> 434325.18 | I6: 0 | J6: 0 | K6: 0 | L6: 0 | M6: 0 | N6: 0 | O6: 0 | P6: 0 | Q6: 0 | R6: 0 | S6: 0 | T6: 0 | U6: 0 | V6: 0 | W6: 0 | X6: 0 | Y6: 0 | Z6: 0 | AA6: 0 | AB6: 0 | AC6: 0 | AD6: 0 | AE6: 0 | AF6: 0 | AG6: 0 | AH6: 0 | AI6: 0 | AJ6: 0 | AK6: 0 | AL6: 0 | AM6: 0 | AN6: 0 | AO6: 0 | AP6: 0 | AQ6: 0 | AR6: 0 | AS6: 0 | AT6: 0 | AU6: 0 | AV6: 0 | AW6: 0 | AX6: 0 | AY6: 0
A7: =IF('Plant Data'!A7="","",'Plant Data'!A7) -> MORUPULE A POWER STATION UNIT 4 | B7: =('Plant Data'!C7*0.85*8760) -> 434325.18 | C7: =('Plant Data'!$C7*0.85*8760) -> 434325.18 | D7: =('Plant Data'!$C7*0.85*8760) -> 434325.18 | E7: =('Plant Data'!$C7*0.85*8760) -> 434325.18 | F7: =('Plant Data'!$C7*0.85*8760) -> 434325.18 | G7: =('Plant Data'!$C7*0.85*8760) -> 434325.18 | H7: =('Plant Data'!$C7*0.85*8760) -> 434325.18 | I7: 0 | J7: 0 | K7: 0 | L7: 0 | M7: 0 | N7: 0 | O7: 0 | P7: 0 | Q7: 0 | R7: 0 | S7: 0 | T7: 0 | U7: 0 | V7: 0 | W7: 0 | X7: 0 | Y7: 0 | Z7: 0 | AA7: 0 | AB7: 0 | AC7: 0 | AD7: 0 | AE7: 0 | AF7: 0 | AG7: 0 | AH7: 0 | AI7: 0 | AJ7: 0 | AK7: 0 | AL7: 0 | AM7: 0 | AN7: 0 | AO7: 0 | AP7: 0 | AQ7: 0 | AR7: 0 | AS7: 0 | AT7: 0 | AU7: 0 | AV7: 0 | AW7: 0 | AX7: 0 | AY7: 0
A8: =IF('Plant Data'!A8="","",'Plant Data'!A8) -> MORUPULE B POWER STATION UNIT 1 | B8: =('Plant Data'!C8*0.85*8760) -> 434325.18 | C8: =('Plant Data'!$C8*0.85*8760) -> 434325.18 | D8: =('Plant Data'!$C8*0.85*8760) -> 434325.18 | E8: =('Plant Data'!$C8*0.85*8760) -> 434325.18 | F8: =('Plant Data'!$C8*0.85*8760) -> 434325.18 | G8: =('Plant Data'!$C8*0.85*8760) -> 434325.18 | H8: =('Plant Data'!$C8*0.85*8760) -> 434325.18 | I8: =('Plant Data'!$C8*0.85*8760) -> 434325.18 | J8: =('Plant Data'!$C8*0.85*8760) -> 434325.18 | ... AE8: =('Plant Data'!$C8*0.85*8760) -> 434325.18 | AF8: =('Plant Data'!AG8*0.85*8760) -> 0 | AG8: =('Plant Data'!AH8*0.85*8760) -> 0 | AH8: =('Plant Data'!AI8*0.85*8760) -> 0 | AI8: =('Plant Data'!AJ8*0.85*8760) -> 0 | AJ8: =('Plant Data'!AK8*0.85*8760) -> 0 | AK8: =('Plant Data'!AL8*0.85*8760) -> 0 | AL8: =('Plant Data'!AM8*0.85*8760) -> 0 | AM8: =('Plant Data'!AN8*0.85*8760) -> 0 | ... AY8: =('Plant Data'!AZ8*0.85*8760) -> 0
A9: =IF('Plant Data'!A9="","",'Plant Data'!A9) -> MORUPULE B POWER STATION UNIT 2 | B9: =('Plant Data'!C9*0.85*8760) -> 434325.18 | C9: =('Plant Data'!$C9*0.85*8760) -> 434325.18 | D9: =('Plant Data'!$C9*0.85*8760) -> 434325.18 | E9: =('Plant Data'!$C9*0.85*8760) -> 434325.18 | F9: =('Plant Data'!$C9*0.85*8760) -> 434325.18 | G9: =('Plant Data'!$C9*0.85*8760) -> 434325.18 | H9: =('Plant Data'!$C9*0.85*8760) -> 434325.18 | I9: =('Plant Data'!$C9*0.85*8760) -> 434325.18 | J9: =('Plant Data'!$C9*0.85*8760) -> 434325.18 | ... AE9: =('Plant Data'!$C9*0.85*8760) -> 434325.18 | AF9: =('Plant Data'!AG9*0.85*8760) -> 0 | AG9: =('Plant Data'!AH9*0.85*8760) -> 0 | AH9: =('Plant Data'!AI9*0.85*8760) -> 0 | AI9: =('Plant Data'!AJ9*0.85*8760) -> 0 | AJ9: =('Plant Data'!AK9*0.85*8760) -> 0 | AK9: =('Plant Data'!AL9*0.85*8760) -> 0 | AL9: =('Plant Data'!AM9*0.85*8760) -> 0 | AM9: =('Plant Data'!AN9*0.85*8760) -> 0 | ... AY9: =('Plant Data'!AZ9*0.85*8760) -> 0
A10: =IF('Plant Data'!A10="","",'Plant Data'!A10) -> MORUPULE B POWER STATION UNIT 3 | B10: =('Plant Data'!C10*0.85*8760) -> 434325.18 | C10: =('Plant Data'!$C10*0.85*8760) -> 434325.18 | D10: =('Plant Data'!$C10*0.85*8760) -> 434325.18 | E10: =('Plant Data'!$C10*0.85*8760) -> 434325.18 | F10: =('Plant Data'!$C10*0.85*8760) -> 434325.18 | G10: =('Plant Data'!$C10*0.85*8760) -> 434325.18 | H10: =('Plant Data'!$C10*0.85*8760) -> 434325.18 | I10: =('Plant Data'!$C10*0.85*8760) -> 434325.18 | J10: =('Plant Data'!$C10*0.85*8760) -> 434325.18 | ... AE10: =('Plant Data'!$C10*0.85*8760) -> 434325.18 | AF10: =('Plant Data'!AG10*0.85*8760) -> 0 | AG10: =('Plant Data'!AH10*0.85*8760) -> 0 | AH10: =('Plant Data'!AI10*0.85*8760) -> 0 | AI10: =('Plant Data'!AJ10*0.85*8760) -> 0 | AJ10: =('Plant Data'!AK10*0.85*8760) -> 0 | AK10: =('Plant Data'!AL10*0.85*8760) -> 0 | AL10: =('Plant Data'!AM10*0.85*8760) -> 0 | AM10: =('Plant Data'!AN10*0.85*8760) -> 0 | ... AY10: =('Plant Data'!AZ10*0.85*8760) -> 0
A11: =IF('Plant Data'!A11="","",'Plant Data'!A11) -> MORUPULE B POWER STATION UNIT 4 | B11: =('Plant Data'!C11*0.85*8760) -> 434325.18 | C11: =('Plant Data'!$C11*0.85*8760) -> 434325.18 | D11: =('Plant Data'!$C11*0.85*8760) -> 434325.18 | E11: =('Plant Data'!$C11*0.85*8760) -> 434325.18 | F11: =('Plant Data'!$C11*0.85*8760) -> 434325.18 | G11: =('Plant Data'!$C11*0.85*8760) -> 434325.18 | H11: =('Plant Data'!$C11*0.85*8760) -> 434325.18 | I11: =('Plant Data'!$C11*0.85*8760) -> 434325.18 | J11: =('Plant Data'!$C11*0.85*8760) -> 434325.18 | ... AE11: =('Plant Data'!$C11*0.85*8760) -> 434325.18 | AF11: =('Plant Data'!AG11*0.85*8760) -> 0 | AG11: =('Plant Data'!AH11*0.85*8760) -> 0 | AH11: =('Plant Data'!AI11*0.85*8760) -> 0 | AI11: =('Plant Data'!AJ11*0.85*8760) -> 0 | AJ11: =('Plant Data'!AK11*0.85*8760) -> 0 | AK11: =('Plant Data'!AL11*0.85*8760) -> 0 | AL11: =('Plant Data'!AM11*0.85*8760) -> 0 | AM11: =('Plant Data'!AN11*0.85*8760) -> 0 | ... AY11: =('Plant Data'!AZ11*0.85*8760) -> 0
A16: =IF('Plant Data'!A16="","",'Plant Data'!A16)
A17: =IF('Plant Data'!A17="","",'Plant Data'!A17)
A18: =IF('Plant Data'!A18="","",'Plant Data'!A18)
A19: =IF('Plant Data'!A19="","",'Plant Data'!A19)
A20: =IF('Plant Data'!A20="","",'Plant Data'!A20)
A21: =IF('Plant Data'!A21="","",'Plant Data'!A21)
A22: =IF('Plant Data'!A22="","",'Plant Data'!A22)
A23: =IF('Plant Data'!A23="","",'Plant Data'!A23)
A24: =IF('Plant Data'!A24="","",'Plant Data'!A24)
A25: =IF('Plant Data'!A25="","",'Plant Data'!A25)
A26: =IF('Plant Data'!A26="","",'Plant Data'!A26)
A27: =IF('Plant Data'!A27="","",'Plant Data'!A27)
... A300: =IF('Plant Data'!A300="","",'Plant Data'!A300)

Sheet Price_Gen
A1: FFRM
A2: Average revenue earned by ALL plants in $/MWh either from market or from a PPA and total coal generation forecast in TWh
A3: Variable | B3: Technology | C3: Scenario | D3: =Definitions!I33 -> 44197 | E3: =IFERROR(IF(EDATE(D3,12)<(Definitions!$I$34+1),EDATE(D3,12),""),"") -> 44562 | F3: =IFERROR(IF(EDATE(E3,12)<(Definitions!$I$34+1),EDATE(E3,12),""),"") -> 44927 | G3: =IFERROR(IF(EDATE(F3,12)<(Definitions!$I$34+1),EDATE(F3,12),""),"") -> 45292 | H3: =IFERROR(IF(EDATE(G3,12)<(Definitions!$I$34+1),EDATE(G3,12),""),"") -> 45658 | I3: =IFERROR(IF(EDATE(H3,12)<(Definitions!$I$34+1),EDATE(H3,12),""),"") -> 46023 | J3: =IFERROR(IF(EDATE(I3,12)<(Definitions!$I$34+1),EDATE(I3,12),""),"") -> 46388 | K3: =IFERROR(IF(EDATE(J3,12)<(Definitions!$I$34+1),EDATE(J3,12),""),"") -> 46753 | L3: =IFERROR(IF(EDATE(K3,12)<(Definitions!$I$34+1),EDATE(K3,12),""),"") -> 47119 | ... BA3: =IFERROR(IF(EDATE(AZ3,12)<(Definitions!$I$34+1),EDATE(AZ3,12),""),"") -> 62094
A4: Marginal Revenue ($/MWh) | C4: Market Price
A5: Marginal Revenue ($/MWh) | C5: PPA | D5: Concerned this was not previously temporally accurate
A6: Marginal Revenue ($/MWh) | C6: Public Utility
A7: Generation Constraint (TWh) | B7: =IF(Definitions!H25="","",Definitions!H25) -> PWRCOA001 | C7: =IF(Definitions!E25="","",Definitions!E25) -> BAU | D7: 10 | E7: 10 | F7: 10 | G7: 10 | H7: 10 | I7: 10 | J7: 10 | K7: 10 | L7: 10 | M7: 10 | N7: 10 | O7: 10 | P7: 10 | Q7: 10 | R7: 2 | S7: 1 | T7: 1 | U7: 1 | V7: 1 | W7: 1 | X7: 1 | Y7: 1 | Z7: 1 | AA7: 1 | AB7: 0 | AC7: 0 | AD7: 0 | AE7: 0 | AF7: 0 | AG7: 0 | AH7: 0 | AI7: 0 | AJ7: 0 | AK7: 0 | AL7: 0 | AM7: 0 | AN7: 0 | AO7: 0 | AP7: 0 | AQ7: 0 | AR7: 0 | AS7: 0 | AT7: 0 | AU7: 0 | AV7: 0 | AW7: 0 | AX7: 0 | AY7: 0 | AZ7: 0 | BA7: 0
A8: Generation Constraint (TWh) | B8: =IF(Definitions!H25="","",Definitions!H25) -> PWRCOA001 | C8: =IF(Definitions!E26="","",Definitions!E26) -> AD | D8: 3 | E8: 3 | F8: 3 | G8: 3 | H8: 3 | I8: 2 | J8: 2 | K8: 2 | L8: 2 | M8: 2 | N8: 2 | O8: 2 | P8: 1 | Q8: 1 | R8: 0 | S8: 0 | T8: 0 | U8: 0 | V8: 0 | W8: 0 | X8: 0 | Y8: 0 | Z8: 0 | AA8: 0 | AB8: 0 | AC8: 0 | AD8: 0 | AE8: 0 | AF8: 0 | AG8: 0 | AH8: 0 | AI8: 0 | AJ8: 0 | AK8: 0 | AL8: 0 | AM8: 0 | AN8: 0 | AO8: 0 | AP8: 0 | AQ8: 0 | AR8: 0 | AS8: 0 | AT8: 0 | AU8: 0 | AV8: 0 | AW8: 0 | AX8: 0 | AY8: 0 | AZ8: 0 | BA8: 0
C12: =IF(Definitions!E30="","",Definitions!E30)
C13: =IF(Definitions!E31="","",Definitions!E31)

Sheet Price_Distribution
A1: FFRM
A2: Price distribution (multiple of average price in Price_Gen over the years A3-K24 in different time blocks and % of time in each time block in column O)
B3: Peak1 | C3: Peak2 | D3: Peak3 | E3: Shouder1 | F3: Shouder2 | G3: Shouder3 | H3: Shouder4 | I3: Shouder5 | J3: Offpeak1 | K3: Offpeak2 | N3: PercentTime
A4: 2021 | B4: 2.6877489 | C4: 2.1857194 | D4: 1.7969712 | E4: 1.4117966 | F4: 1.114336 | G4: 0.90690841 | H4: 0.76110007 | I4: 0.63570875 | J4: 0.49254048 | K4: 0.0014147339 | M4: Peak1 | N4: 0.02
A5: =A4+1 -> 2022 | B5: 2.6877489 | C5: 2.1857194 | D5: 1.7969712 | E5: 1.4117966 | F5: 1.114336 | G5: 0.90690841 | H5: 0.76110007 | I5: 0.63570875 | J5: 0.49254048 | K5: 0.0014147339 | M5: Peak2 | N5: 0.03
A6: =A5+1 -> 2023 | B6: 2.6877489 | C6: 2.1857194 | D6: 1.7969712 | E6: 1.4117966 | F6: 1.114336 | G6: 0.90690841 | H6: 0.76110007 | I6: 0.63570875 | J6: 0.49254048 | K6: 0.0014147339 | M6: Peak3 | N6: 0.04
A7: =A6+1 -> 2024 | B7: 2.6877489 | C7: 2.1857194 | D7: 1.7969712 | E7: 1.4117966 | F7: 1.114336 | G7: 0.90690841 | H7: 0.76110007 | I7: 0.63570875 | J7: 0.49254048 | K7: 0.0014147339 | M7: Shouder1 | N7: 0.05
A8: =A7+1 -> 2025 | B8: 2.6877489 | C8: 2.1857194 | D8: 1.7969712 | E8: 1.4117966 | F8: 1.114336 | G8: 0.90690841 | H8: 0.76110007 | I8: 0.63570875 | J8: 0.49254048 | K8: 0.0014147339 | M8: Shouder2 | N8: 0.05
A9: =A8+1 -> 2026 | B9: 2.6877489 | C9: 2.1857194 | D9: 1.7969712 | E9: 1.4117966 | F9: 1.114336 | G9: 0.90690841 | H9: 0.76110007 | I9: 0.63570875 | J9: 0.49254048 | K9: 0.0014147339 | M9: Shouder3 | N9: 0.05
A10: =A9+1 -> 2027 | B10: 2.6877489 | C10: 2.1857194 | D10: 1.7969712 | E10: 1.4117966 | F10: 1.114336 | G10: 0.90690841 | H10: 0.76110007 | I10: 0.63570875 | J10: 0.49254048 | K10: 0.0014147339 | M10: Shouder4 | N10: 0.31
A11: =A10+1 -> 2028 | B11: 2.6877489 | C11: 2.1857194 | D11: 1.7969712 | E11: 1.4117966 | F11: 1.114336 | G11: 0.90690841 | H11: 0.76110007 | I11: 0.63570875 | J11: 0.49254048 | K11: 0.0014147339 | M11: Shouder5 | N11: 0.15
A12: =A11+1 -> 2029 | B12: 2.6877489 | C12: 2.1857194 | D12: 1.7969712 | E12: 1.4117966 | F12: 1.114336 | G12: 0.90690841 | H12: 0.76110007 | I12: 0.63570875 | J12: 0.49254048 | K12: 0.0014147339 | M12: Offpeak1 | N12: 0.15
A13: =A12+1 -> 2030 | B13: 2.6877489 | C13: 2.1857194 | D13: 1.7969712 | E13: 1.4117966 | F13: 1.114336 | G13: 0.90690841 | H13: 0.76110007 | I13: 0.63570875 | J13: 0.49254048 | K13: 0.0014147339 | M13: Offpeak2 | N13: 0.15
A14: =A13+1 -> 2031 | B14: 2.6877489 | C14: 2.1857194 | D14: 1.7969712 | E14: 1.4117966 | F14: 1.114336 | G14: 0.90690841 | H14: 0.76110007 | I14: 0.63570875 | J14: 0.49254048 | K14: 0.0014147339 | N14: =SUM(N4:N13) -> 1
A15: =A14+1 -> 2032 | B15: 2.6877489 | C15: 2.1857194 | D15: 1.7969712 | E15: 1.4117966 | F15: 1.114336 | G15: 0.90690841 | H15: 0.76110007 | I15: 0.63570875 | J15: 0.49254048 | K15: 0.0014147339
A16: =A15+1 -> 2033 | B16: 2.6877489 | C16: 2.1857194 | D16: 1.7969712 | E16: 1.4117966 | F16: 1.114336 | G16: 0.90690841 | H16: 0.76110007 | I16: 0.63570875 | J16: 0.49254048 | K16: 0.0014147339
A17: =A16+1 -> 2034 | B17: 2.6877489 | C17: 2.1857194 | D17: 1.7969712 | E17: 1.4117966 | F17: 1.114336 | G17: 0.90690841 | H17: 0.76110007 | I17: 0.63570875 | J17: 0.49254048 | K17: 0.0014147339
A18: =A17+1 -> 2035 | B18: 2.6877489 | C18: 2.1857194 | D18: 1.7969712 | E18: 1.4117966 | F18: 1.114336 | G18: 0.90690841 | H18: 0.76110007 | I18: 0.63570875 | J18: 0.49254048 | K18: 0.0014147339
A19: =A18+1 -> 2036 | B19: 2.6877489 | C19: 2.1857194 | D19: 1.7969712 | E19: 1.4117966 | F19: 1.114336 | G19: 0.90690841 | H19: 0.76110007 | I19: 0.63570875 | J19: 0.49254048 | K19: 0.0014147339
A20: =A19+1 -> 2037 | B20: 2.6877489 | C20: 2.1857194 | D20: 1.7969712 | E20: 1.4117966 | F20: 1.114336 | G20: 0.90690841 | H20: 0.76110007 | I20: 0.63570875 | J20: 0.49254048 | K20: 0.0014147339
A21: =A20+1 -> 2038 | B21: 2.6877489 | C21: 2.1857194 | D21: 1.7969712 | E21: 1.4117966 | F21: 1.114336 | G21: 0.90690841 | H21: 0.76110007 | I21: 0.63570875 | J21: 0.49254048 | K21: 0.0014147339
A22: =A21+1 -> 2039 | B22: 2.6877489 | C22: 2.1857194 | D22: 1.7969712 | E22: 1.4117966 | F22: 1.114336 | G22: 0.90690841 | H22: 0.76110007 | I22: 0.63570875 | J22: 0.49254048 | K22: 0.0014147339
A23: =A22+1 -> 2040 | B23: 2.6877489 | C23: 2.1857194 | D23: 1.7969712 | E23: 1.4117966 | F23: 1.114336 | G23: 0.90690841 | H23: 0.76110007 | I23: 0.63570875 | J23: 0.49254048 | K23: 0.0014147339
A24: =A23+1 -> 2041 | B24: 2.6877489 | C24: 2.1857194 | D24: 1.7969712 | E24: 1.4117966 | F24: 1.114336 | G24: 0.90690841 | H24: 0.76110007 | I24: 0.63570875 | J24: 0.49254048 | K24: 0.0014147339
A25: =A24+1 -> 2042 | B25: 2.6877489 | C25: 2.1857194 | D25: 1.7969712 | E25: 1.4117966 | F25: 1.114336 | G25: 0.90690841 | H25: 0.76110007 | I25: 0.63570875 | J25: 0.49254048 | K25: 0.0014147339
A26: =A25+1 -> 2043 | B26: 2.6877489 | C26: 2.1857194 | D26: 1.7969712 | E26: 1.4117966 | F26: 1.114336 | G26: 0.90690841 | H26: 0.76110007 | I26: 0.63570875 | J26: 0.49254048 | K26: 0.0014147339
... A53: =A52+1 -> 2070 | B53: 2.6877489 | C53: 2.1857194 | D53: 1.7969712 | E53: 1.4117966 | F53: 1.114336 | G53: 0.90690841 | H53: 0.76110007 | I53: 0.63570875 | J53: 0.49254048 | K53: 0.0014147339
